Workbook

Sheet Összefoglaló
A1: Aurora Dynamics Kft. – 2025. évi összesített bevételi és kiadási jelentés
A2: Szolgáltatásonkénti és negyedéves bontás – a részletes tételek a megfelelő munkalapokon találhatók
A4: 2025. évi teljes bevétel | E4: 2025. évi teljes kiadás | I4: 2025. évi eredmény | M4: Eredményhányad
A5: ='Cloud integráció'!E69+Webfejlesztés!E65+Tanácsadás!E63 -> 46971500 | E5: ='Cloud integráció'!E70+Webfejlesztés!E66+Tanácsadás!E64 -> 23250000 | I5: =A5-E5 -> 23721500 | M5: =I5/A5 -> 0.505019
A7: Negyedév | B7: Cloud integráció | E7: Webfejlesztés | H7: Tanácsadás | K7: Vállalati összesen
B8: Bevétel (Ft) | C8: Kiadás (Ft) | D8: Eredmény (Ft) | E8: Bevétel (Ft) | F8: Kiadás (Ft) | G8: Eredmény (Ft) | H8: Bevétel (Ft) | I8: Kiadás (Ft) | J8: Eredmény (Ft) | K8: Bevétel (Ft) | L8: Kiadás (Ft) | M8: Eredmény (Ft)
A9: I. negyedév | B9: ='Cloud integráció'!E16 -> 5550000 | C9: ='Cloud integráció'!E17 -> 2830000 | D9: ='Cloud integráció'!E18 -> 2720000 | E9: =Webfejlesztés!E15 -> 2545000 | F9: =Webfejlesztés!E16 -> 1510000 | G9: =Webfejlesztés!E17 -> 1035000 | H9: =Tanácsadás!E14 -> 2208500 | I9: =Tanácsadás!E15 -> 1155000 | J9: =Tanácsadás!E16 -> 1053500 | K9: =B9+E9+H9 -> 10303500 | L9: =C9+F9+I9 -> 5495000 | M9: =D9+G9+J9 -> 4808500
A10: II. negyedév | B10: ='Cloud integráció'!E32 -> 6250000 | C10: ='Cloud integráció'!E33 -> 3010000 | D10: ='Cloud integráció'!E34 -> 3240000 | E10: =Webfejlesztés!E30 -> 2885000 | F10: =Webfejlesztés!E31 -> 1665000 | G10: =Webfejlesztés!E32 -> 1220000 | H10: =Tanácsadás!E29 -> 2290000 | I10: =Tanácsadás!E30 -> 1170000 | J10: =Tanácsadás!E31 -> 1120000 | K10: =B10+E10+H10 -> 11425000 | L10: =C10+F10+I10 -> 5845000 | M10: =D10+G10+J10 -> 5580000
A11: III. negyedév | B11: ='Cloud integráció'!E48 -> 6430000 | C11: ='Cloud integráció'!E49 -> 3045000 | D11: ='Cloud integráció'!E50 -> 3385000 | E11: =Webfejlesztés!E45 -> 3165000 | F11: =Webfejlesztés!E46 -> 1615000 | G11: =Webfejlesztés!E47 -> 1550000 | H11: =Tanácsadás!E43 -> 2363000 | I11: =Tanácsadás!E44 -> 1185000 | J11: =Tanácsadás!E45 -> 1178000 | K11: =B11+E11+H11 -> 11958000 | L11: =C11+F11+I11 -> 5845000 | M11: =D11+G11+J11 -> 6113000
A12: IV. negyedév | B12: ='Cloud integráció'!E64 -> 6950000 | C12: ='Cloud integráció'!E65 -> 3180000 | D12: ='Cloud integráció'!E66 -> 3770000 | E12: =Webfejlesztés!E60 -> 3465000 | F12: =Webfejlesztés!E61 -> 1645000 | G12: =Webfejlesztés!E62 -> 1820000 | H12: =Tanácsadás!E58 -> 2870000 | I12: =Tanácsadás!E59 -> 1240000 | J12: =Tanácsadás!E60 -> 1630000 | K12: =B12+E12+H12 -> 13285000 | L12: =C12+F12+I12 -> 6065000 | M12: =D12+G12+J12 -> 7220000
A13: 2025. évi összesen | B13: =SUM(B9:B12) -> 25180000 | C13: =SUM(C9:C12) -> 12065000 | D13: =SUM(D9:D12) -> 13115000 | E13: =SUM(E9:E12) -> 12060000 | F13: =SUM(F9:F12) -> 6435000 | G13: =SUM(G9:G12) -> 5625000 | H13: =SUM(H9:H12) -> 9731500 | I13: =SUM(I9:I12) -> 4750000 | ... M13: =SUM(M9:M12) -> 23721500
A15: Az összefoglaló táblázat minden cellája a három szolgáltatási munkalap negyedéves részösszegeire mutató élő hivatkozás (képlet); a részletes, tételes bontás az adott munkalapokon tekinthető meg.

Sheet Cloud integráció
A1: Aurora Dynamics Kft. – Bevételi és kiadási jelentés 2025
A2: Cloud integrációs szolgáltatások (AWS, Azure, GCP)
A3: Az összegek nettó, forintban (Ft) kifejezett értékek.
A5: I. negyedév (2025.01.01 – 2025.03.31)
A6: Dátum | B6: Tétel megnevezése | C6: Partner | D6: Típus | E6: Összeg (Ft)
A7: 45671 | B7: AWS Landing Zone kialakítása | C7: Nimbus Trade Kft. | D7: Bevétel | E7: 1450000
A8: 45691 | B8: Kubernetes fürt kiépítése (EKS) | C8: Voxel Systems Zrt. | D8: Bevétel | E8: 1250000
A9: 45708 | B9: Havi üzemeltetési támogatás (3 ügyfél) | C9: Vegyes ügyfélkör | D9: Bevétel | E9: 1020000
A10: 45727 | B10: Terraform/OpenTofu bevezetés | C10: Delta Cloud Kft. | D10: Bevétel | E10: 980000
A11: 45741 | B11: Cloud felkészültségi felmérés | C11: Solaris Trade Kft. | D11: Bevétel | E11: 850000
A12: 45688 | B12: Bérköltség (DevOps mérnökök, allokált) | C12: Belső | D12: Kiadás | E12: 1800000
A13: 45698 | B13: Alvállalkozói díj – biztonsági audit | C13: KyberGuard Kft. | D13: Kiadás | E13: 600000
A14: 45721 | B14: Szoftverlicencek (Terraform Cloud, monitoring) | C14: Vegyes beszállító | D14: Kiadás | E14: 180000
A15: 45736 | B15: Teszt- és demókörnyezet felhőköltsége | C15: AWS / Azure / GCP | D15: Kiadás | E15: 250000
A16: I. negyedévi bevétel összesen | E16: =SUM(E7:E11) -> 5550000
A17: I. negyedévi kiadás összesen | E17: =SUM(E12:E15) -> 2830000
A18: I. negyedévi eredmény | E18: =E16-E17 -> 2720000
A20: II. negyedév (2025.04.01 – 2025.06.30)
A21: Dátum | B21: Tétel megnevezése | C21: Partner | D21: Típus | E21: Összeg (Ft)
A22: 45756 | B22: Landing Zone kialakítása (Azure) | C22: Prisma Ipari Kft. | D22: Bevétel | E22: 1450000
A23: 45775 | B23: Kubernetes fürt kiépítése (GKE) | C23: ByteForge Kft. | D23: Bevétel | E23: 1250000
A24: 45792 | B24: Havi üzemeltetési támogatás (4 ügyfél) | C24: Vegyes ügyfélkör | D24: Bevétel | E24: 1360000
A25: 45807 | B25: CI/CD pipeline kialakítása (GitOps) | C25: Delta Cloud Kft. | D25: Bevétel | E25: 780000
A26: 45826 | B26: Biztonsági audit és megfelelőségi felmérés | C26: Solaris Trade Kft. | D26: Bevétel | E26: 690000
A27: 45834 | B27: Multi-cloud hálózati integráció | C27: Northline Trade Kft. | D27: Bevétel | E27: 720000
A28: 45777 | B28: Bérköltség (DevOps mérnökök, allokált) | C28: Belső | D28: Kiadás | E28: 1900000
A29: 45789 | B29: Alvállalkozói díj – hálózati integráció | C29: NetBridge Kft. | D29: Kiadás | E29: 650000
A30: 45814 | B30: Szoftverlicencek | C30: Vegyes beszállító | D30: Kiadás | E30: 190000
A31: 45832 | B31: Teszt- és demókörnyezet felhőköltsége | C31: AWS / Azure / GCP | D31: Kiadás | E31: 270000
A32: II. negyedévi bevétel összesen | E32: =SUM(E22:E27) -> 6250000
A33: II. negyedévi kiadás összesen | E33: =SUM(E28:E31) -> 3010000
A34: II. negyedévi eredmény | E34: =E32-E33 -> 3240000
A36: III. negyedév (2025.07.01 – 2025.09.30)
A37: Dátum | B37: Tétel megnevezése | C37: Partner | D37: Típus | E37: Összeg (Ft)
A38: 45848 | B38: Landing Zone kialakítása (GCP) | C38: Northline Trade Kft. | D38: Bevétel | E38: 1450000
A39: 45867 | B39: Kubernetes fürt kiépítése (AKS) | C39: Prisma Ipari Kft. | D39: Bevétel | E39: 1250000
A40: 45883 | B40: Havi üzemeltetési támogatás (5 ügyfél) | C40: Vegyes ügyfélkör | D40: Bevétel | E40: 1700000
A41: 45896 | B41: Szolgáltatáshálózat (Service Mesh) bevezetése | C41: ByteForge Kft. | D41: Bevétel | E41: 990000
A42: 45909 | B42: Katasztrófa-helyreállítási tervezés | C42: Northline Trade Kft. | D42: Bevétel | E42: 560000
A43: 45922 | B43: Költségoptimalizálási felülvizsgálat (FinOps) | C43: Delta Cloud Kft. | D43: Bevétel | E43: 480000
...

Sheet Webfejlesztés
A1: Aurora Dynamics Kft. – Bevételi és kiadási jelentés 2025
A2: Webfejlesztési szolgáltatások
A3: Az összegek nettó, forintban (Ft) kifejezett értékek.
A5: I. negyedév (2025.01.01 – 2025.03.31)
A6: Dátum | B6: Tétel megnevezése | C6: Partner | D6: Típus | E6: Összeg (Ft)
A7: 45677 | B7: Bemutatkozó weboldal (landing page) | C7: Kertész Bt. | D7: Bevétel | E7: 280000
A8: 45693 | B8: Vállalati weboldal (aloldalakkal) | C8: Aurex Kereskedelmi Zrt. | D8: Bevétel | E8: 650000
A9: 45706 | B9: Webáruház alapcsomag kialakítása | C9: GreenLeaf Bio Kft. | D9: Bevétel | E9: 950000
A10: 45726 | B10: Karbantartási csomag (I. negyedév) | C10: Vegyes ügyfélkör | D10: Bevétel | E10: 195000
A11: 45740 | B11: API fejlesztés és rendszerintegráció | C11: Northline Trade Kft. | D11: Bevétel | E11: 470000
A12: 45688 | B12: Bérköltség (fejlesztők, allokált) | C12: Belső | D12: Kiadás | E12: 1200000
A13: 45702 | B13: Alvállalkozói díj – dizájn | C13: PixelCraft Stúdió | D13: Kiadás | E13: 220000
A14: 45723 | B14: Szoftverlicencek (hosting, CMS) | C14: Vegyes beszállító | D14: Kiadás | E14: 90000
A15: I. negyedévi bevétel összesen | E15: =SUM(E7:E11) -> 2545000
A16: I. negyedévi kiadás összesen | E16: =SUM(E12:E14) -> 1510000
A17: I. negyedévi eredmény | E17: =E15-E16 -> 1035000
A19: II. negyedév (2025.04.01 – 2025.06.30)
A20: Dátum | B20: Tétel megnevezése | C20: Partner | D20: Típus | E20: Összeg (Ft)
A21: 45755 | B21: Vállalati weboldal (aloldalakkal) | C21: Solaris Trade Kft. | D21: Bevétel | E21: 650000
A22: 45769 | B22: Webáruház alapcsomag kialakítása | C22: Kertész Bt. | D22: Bevétel | E22: 950000
A23: 45790 | B23: Egyedi webalkalmazás fejlesztése (40 óra) | C23: ByteForge Kft. | D23: Bevétel | E23: 880000
A24: 45806 | B24: Karbantartási csomag (II. negyedév) | C24: Vegyes ügyfélkör | D24: Bevétel | E24: 195000
A25: 45824 | B25: Teljesítményoptimalizálás és SEO alapcsomag | C25: GreenLeaf Bio Kft. | D25: Bevétel | E25: 210000
A26: 45777 | B26: Bérköltség (fejlesztők, allokált) | C26: Belső | D26: Kiadás | E26: 1250000
A27: 45793 | B27: Alvállalkozói díj – dizájn | C27: PixelCraft Stúdió | D27: Kiadás | E27: 230000
A28: 45817 | B28: Szoftverlicencek (hosting, CMS) | C28: Vegyes beszállító | D28: Kiadás | E28: 95000
A29: 45835 | B29: Fizetési és szállítási integráció | C29: Külső alvállalkozó | D29: Kiadás | E29: 90000
A30: II. negyedévi bevétel összesen | E30: =SUM(E21:E25) -> 2885000
A31: II. negyedévi kiadás összesen | E31: =SUM(E26:E29) -> 1665000
A32: II. negyedévi eredmény | E32: =E30-E31 -> 1220000
A34: III. negyedév (2025.07.01 – 2025.09.30)
A35: Dátum | B35: Tétel megnevezése | C35: Partner | D35: Típus | E35: Összeg (Ft)
A36: 45849 | B36: Bemutatkozó weboldal (landing page) | C36: Vortex Digital Kft. | D36: Bevétel | E36: 280000
A37: 45862 | B37: Vállalati weboldal (aloldalakkal) | C37: Aurex Kereskedelmi Zrt. | D37: Bevétel | E37: 650000
A38: 45881 | B38: Webáruház alapcsomag kialakítása | C38: Northline Trade Kft. | D38: Bevétel | E38: 950000
A39: 45897 | B39: Tartalomkezelő rendszer (CMS) testreszabása | C39: Prisma Ipari Kft. | D39: Bevétel | E39: 320000
A40: 45910 | B40: Karbantartási csomag (III. negyedév) | C40: Vegyes ügyfélkör | D40: Bevétel | E40: 195000
A41: 45925 | B41: Egyedi webalkalmazás fejlesztése (35 óra) | C41: Delta Cloud Kft. | D41: Bevétel | E41: 770000
A42: 45869 | B42: Bérköltség (fejlesztők, allokált) | C42: Belső | D42: Kiadás | E42: 1280000
A43: 45887 | B43: Alvállalkozói díj – dizájn | C43: PixelCraft Stúdió | D43: Kiadás | E43: 235000
...

Sheet Tanácsadás
A1: Aurora Dynamics Kft. – Bevételi és kiadási jelentés 2025
A2: Tanácsadási szolgáltatások
A3: Az összegek nettó, forintban (Ft) kifejezett értékek.
A5: I. negyedév (2025.01.01 – 2025.03.31)
A6: Dátum | B6: Tétel megnevezése | C6: Partner | D6: Típus | E6: Összeg (Ft)
A7: 45673 | B7: Stratégiai IT-tanácsadás (12 óra) | C7: Aurex Kereskedelmi Zrt. | D7: Bevétel | E7: 456000
A8: 45699 | B8: Digitális transzformációs felmérés | C8: Solaris Trade Kft. | D8: Bevétel | E8: 890000
A9: 45722 | B9: Projektmenedzsment tanácsadás (15 óra) | C9: Northline Trade Kft. | D9: Bevétel | E9: 442500
A10: 45735 | B10: Vezetői workshop és stratégiai tervezés | C10: Prisma Ipari Kft. | D10: Bevétel | E10: 420000
A11: 45688 | B11: Bérköltség (tanácsadók, allokált) | C11: Belső | D11: Kiadás | E11: 950000
A12: 45708 | B12: Utazási és rezsiköltség | C12: Vegyes | D12: Kiadás | E12: 85000
A13: 45730 | B13: Szakmai továbbképzés és tanúsítványok | C13: Vegyes szolgáltató | D13: Kiadás | E13: 120000
A14: I. negyedévi bevétel összesen | E14: =SUM(E7:E10) -> 2208500
A15: I. negyedévi kiadás összesen | E15: =SUM(E11:E13) -> 1155000
A16: I. negyedévi eredmény | E16: =E14-E15 -> 1053500
A18: II. negyedév (2025.04.01 – 2025.06.30)
A19: Dátum | B19: Tétel megnevezése | C19: Partner | D19: Típus | E19: Összeg (Ft)
A20: 45757 | B20: Csapatmentorálás és technikai coaching (1 hó) | C20: ByteForge Kft. | D20: Bevétel | E20: 260000
A21: 45771 | B21: Architektúra-felülvizsgálat | C21: Delta Cloud Kft. | D21: Bevétel | E21: 540000
A22: 45792 | B22: Folyamatoptimalizálási workshop | C22: Aurex Kereskedelmi Zrt. | D22: Bevétel | E22: 350000
A23: 45805 | B23: Stratégiai IT-tanácsadás (10 óra) | C23: Prisma Ipari Kft. | D23: Bevétel | E23: 380000
A24: 45813 | B24: Kockázatelemzés és megfelelőségi tanácsadás | C24: Vortex Digital Kft. | D24: Bevétel | E24: 610000
A25: 45831 | B25: Utókövetéses konzultáció (retainer, 1 hó) | C25: Northline Trade Kft. | D25: Bevétel | E25: 150000
A26: 45777 | B26: Bérköltség (tanácsadók, allokált) | C26: Belső | D26: Kiadás | E26: 970000
A27: 45794 | B27: Utazási és rezsiköltség | C27: Vegyes | D27: Kiadás | E27: 90000
A28: 45819 | B28: Szakmai továbbképzés és tanúsítványok | C28: Vegyes szolgáltató | D28: Kiadás | E28: 110000
A29: II. negyedévi bevétel összesen | E29: =SUM(E20:E25) -> 2290000
A30: II. negyedévi kiadás összesen | E30: =SUM(E26:E28) -> 1170000
A31: II. negyedévi eredmény | E31: =E29-E30 -> 1120000
A33: III. negyedév (2025.07.01 – 2025.09.30)
A34: Dátum | B34: Tétel megnevezése | C34: Partner | D34: Típus | E34: Összeg (Ft)
A35: 45852 | B35: Stratégiai IT-tanácsadás (14 óra) | C35: Prisma Ipari Kft. | D35: Bevétel | E35: 532000
A36: 45868 | B36: Digitális transzformációs felmérés | C36: ByteForge Kft. | D36: Bevétel | E36: 890000
A37: 45888 | B37: Csapatmentorálás és technikai coaching (1 hó) | C37: Delta Cloud Kft. | D37: Bevétel | E37: 260000
A38: 45908 | B38: Projektmenedzsment tanácsadás (18 óra) | C38: Aurex Kereskedelmi Zrt. | D38: Bevétel | E38: 531000
A39: 45924 | B39: Utókövetéses konzultáció (retainer, 1 hó) | C39: Northline Trade Kft. | D39: Bevétel | E39: 150000
A40: 45869 | B40: Bérköltség (tanácsadók, allokált) | C40: Belső | D40: Kiadás | E40: 990000
A41: 45890 | B41: Utazási és rezsiköltség | C41: Vegyes | D41: Kiadás | E41: 95000
A42: 45913 | B42: Szakmai továbbképzés és tanúsítványok | C42: Vegyes szolgáltató | D42: Kiadás | E42: 100000
A43: III. negyedévi bevétel összesen | E43: =SUM(E35:E39) -> 2363000
...
